Workbook

Sheet Auction
A1: Chennai Super Kings (CSK) | C1: =(100000000 - SUM(B4:B15)) -> 73100000 | E1: Royal Challengers Bengaluru (RCB) | G1: =(100000000 - SUM(F4:F15)) -> 58500000 | I1: Mumbai Indians (MI) | K1: =(100000000 - SUM(J4:J15)) -> 47400000 | M1: Delhi Capitals (DC) | O1: =(100000000 - SUM(N4:N15)) -> 59100000
A3: Players | B3: Purchase Price | C3: Category | E3: Players | F3: Purchase Price | G3: Category | I3: Players | J3: Purchase Price | K3: Category | M3: Players | N3: Purchase Price | O3: Category
A4: Phil Salt | B4: 10400000 | C4: =IFNA(VLOOKUP(A4,'Player List'!A2:F70,4,FALSE),) -> Overseas | E4: Rashid Khan | F4: 20100000 | G4: =IFNA(VLOOKUP(E4,'Player List'!A12:F80,4,FALSE),) -> Overseas | I4: Cameron Green | J4: 21300000 | K4: =IFNA(VLOOKUP(I4,'Player List'!A2:F70,4,FALSE),) -> Overseas | M4: Shikhar Dhawan | N4: 15300000 | O4: =IFNA(VLOOKUP(M4,'Player List'!A15:F83,4,FALSE),) -> Indian
A5: Venkatesh Iyer | B5: 6100000 | C5: =IFNA(VLOOKUP(A5,'Player List'!A3:F71,4,FALSE),) -> Indian | E5: Mandeep Singh | F5: 11100000 | G5: =IFNA(VLOOKUP(E5,'Player List'!A13:F81,4,FALSE),) -> Indian | I5: Andre Russell | J5: 20200000 | K5: =IFNA(VLOOKUP(I5,'Player List'!A3:F71,4,FALSE),) -> Overseas | M5: Murugan Ashwin | N5: 10200000 | O5: =IFNA(VLOOKUP(M5,'Player List'!A16:F84,4,FALSE),) -> Indian
A6: Dinesh Karthik | B6: 10400000 | C6: =IFNA(VLOOKUP(A6,'Player List'!A4:F72,4,FALSE),) -> Indian | E6: Washington Sundar | F6: 10300000 | G6: =IFNA(VLOOKUP(E6,'Player List'!A14:F82,4,FALSE),) -> Indian | I6: Manish Pandey | J6: 11100000 | K6: =IFNA(VLOOKUP(I6,'Player List'!A4:F72,4,FALSE),) -> Indian | M6: Josh Hazlewood | N6: 15400000 | O6: =IFNA(VLOOKUP(M6,'Player List'!A17:F85,4,FALSE),) -> Overseas
C7: =IFNA(VLOOKUP(A7,'Player List'!A5:F73,4,FALSE),) | G7: =IFNA(VLOOKUP(E7,'Player List'!A15:F83,4,FALSE),) | K7: =IFNA(VLOOKUP(I7,'Player List'!A5:F73,4,FALSE),) | O7: =IFNA(VLOOKUP(M7,'Player List'!A18:F86,4,FALSE),)
C8: =IFNA(VLOOKUP(A8,'Player List'!A6:F74,4,FALSE),) | G8: =IFNA(VLOOKUP(E8,'Player List'!A16:F84,4,FALSE),) | K8: =IFNA(VLOOKUP(I8,'Player List'!A6:F74,4,FALSE),) | O8: =IFNA(VLOOKUP(M8,'Player List'!A19:F87,4,FALSE),)
C9: =IFNA(VLOOKUP(A9,'Player List'!A7:F75,4,FALSE),) | G9: =IFNA(VLOOKUP(E9,'Player List'!A17:F85,4,FALSE),) | K9: =IFNA(VLOOKUP(I9,'Player List'!A7:F75,4,FALSE),) | O9: =IFNA(VLOOKUP(M9,'Player List'!A20:F88,4,FALSE),)
C10: =IFNA(VLOOKUP(A10,'Player List'!A8:F76,4,FALSE),) | G10: =IFNA(VLOOKUP(E10,'Player List'!A18:F86,4,FALSE),) | K10: =IFNA(VLOOKUP(I10,'Player List'!A8:F76,4,FALSE),) | O10: =IFNA(VLOOKUP(M10,'Player List'!A21:F89,4,FALSE),)
C11: =IFNA(VLOOKUP(A11,'Player List'!A9:F77,4,FALSE),) | G11: =IFNA(VLOOKUP(E11,'Player List'!A19:F87,4,FALSE),) | K11: =IFNA(VLOOKUP(I11,'Player List'!A9:F77,4,FALSE),) | O11: =IFNA(VLOOKUP(M11,'Player List'!A22:F90,4,FALSE),)
C12: =IFNA(VLOOKUP(A12,'Player List'!A10:F78,4,FALSE),) | G12: =IFNA(VLOOKUP(E12,'Player List'!A20:F88,4,FALSE),) | K12: =IFNA(VLOOKUP(I12,'Player List'!A10:F78,4,FALSE),) | O12: =IFNA(VLOOKUP(M12,'Player List'!A23:F91,4,FALSE),)
C13: =IFNA(VLOOKUP(A13,'Player List'!A11:F79,4,FALSE),) | G13: =IFNA(VLOOKUP(E13,'Player List'!A21:F89,4,FALSE),) | K13: =IFNA(VLOOKUP(I13,'Player List'!A11:F79,4,FALSE),) | O13: =IFNA(VLOOKUP(M13,'Player List'!A24:F92,4,FALSE),)
C14: =IFNA(VLOOKUP(A14,'Player List'!A12:F80,4,FALSE),) | G14: =IFNA(VLOOKUP(E14,'Player List'!A22:F90,4,FALSE),) | K14: =IFNA(VLOOKUP(I14,'Player List'!A12:F80,4,FALSE),) | O14: =IFNA(VLOOKUP(M14,'Player List'!A25:F93,4,FALSE),)
C15: =IFNA(VLOOKUP(A15,'Player List'!A13:F81,4,FALSE),) | G15: =IFNA(VLOOKUP(E15,'Player List'!A23:F91,4,FALSE),) | K15: =IFNA(VLOOKUP(I15,'Player List'!A13:F81,4,FALSE),) | O15: =IFNA(VLOOKUP(M15,'Player List'!A26:F94,4,FALSE),)
A17: ALL BIDS ARE IN 100,000 INCREMENTS | E17: ALL BIDS ARE IN 100,000 INCREMENTS | I17: ALL BIDS ARE IN 100,000 INCREMENTS | M17: ALL BIDS ARE IN 100,000 INCREMENTS
A18: BIDS ON PLAYER | E18: BIDS ON PLAYER | I18: BIDS ON PLAYER | M18: BIDS ON PLAYER
A21: Total Indians | C21: =COUNTIF(C4:C15,"Indian") -> 2 | E21: Total Indians | G21: =COUNTIF(G4:G15,"Indian") -> 2 | I21: Total Indians | K21: =COUNTIF(K4:K15,"Indian") -> 1 | M21: Total Indians | O21: =COUNTIF(O4:O15,"Indian") -> 2
A22: Total Overseas | C22: =COUNTIF(C4:C15, "Overseas") -> 1 | E22: Total Overseas | G22: =COUNTIF(G4:G15, "Overseas") -> 1 | I22: Total Overseas | K22: =COUNTIF(K4:K15, "Overseas") -> 2 | M22: Total Overseas | O22: =COUNTIF(O4:O15, "Overseas") -> 1
A23: Total Players | C23: =SUM(C21:C22) -> 3 | E23: Total Players | G23: =SUM(G21:G22) -> 3 | I23: Total Players | K23: =SUM(K21:K22) -> 3 | M23: Total Players | O23: =SUM(O21:O22) -> 3
A26: PLAYER IN BID | C26: ='Player List'!J1 -> Mayank Agarwal | I26: Players Left | J26: =COUNTIF('Player List'!E2:E70 , "Unsold") -> 57 | K26: Last Player Sold | M26: Washington Sundar
K27: Bid By Team | M27: Royal Challengers Bengaluru (RCB)
A28: Base Price | C28: =IFERROR(VLOOKUP(C26, 'Player List'!A:B, 2, FALSE), "") -> 10000000 | K28: Sale Price | M28: 10300000
A29: Current Price | I29: Players Sold | J29: =COUNTIF('Player List'!E2:E70 , "Sold") -> 12
A30: Bid By Team

Sheet Player List
A1: Player Name | B1: Base Price (₹) | C1: Selling Price | D1: Category | E1: Status | F1: Sold To | I1: Next Random Player | J1: Mayank Agarwal
A2: Virat Kohli | B2: 20000000 | D2: Indian | E2: Unsold
A3: Rohit Sharma | B3: 20000000 | D3: Indian | E3: Unsold
A4: MS Dhoni | B4: 20000000 | D4: Indian | E4: Unsold
A5: AB de Villiers | B5: 20000000 | D5: Overseas | E5: Unsold
A6: David Warner | B6: 20000000 | D6: Overseas | E6: Unsold
A7: Hardik Pandya | B7: 20000000 | D7: Indian | E7: Unsold
A8: Jasprit Bumrah | B8: 20000000 | D8: Indian | E8: Unsold
A9: KL Rahul | B9: 20000000 | D9: Indian | E9: Unsold
A10: Andre Russell | B10: 20000000 | C10: 20200000 | D10: Overseas | E10: Sold | F10: Mumbai Indians (MI)
A11: Ben Stokes | B11: 20000000 | D11: Overseas | E11: Unsold
A12: Jos Buttler | B12: 20000000 | D12: Overseas | E12: Unsold
A13: Rashid Khan | B13: 20000000 | C13: 20100000 | D13: Overseas | E13: Sold | F13: Royal Challengers Bengaluru (RCB)
A14: Pat Cummins | B14: 20000000 | D14: Overseas | E14: Unsold
A15: Faf du Plessis | B15: 20000000 | D15: Overseas | E15: Unsold
A16: Glenn Maxwell | B16: 20000000 | D16: Overseas | E16: Unsold
A17: Sam Curran | B17: 20000000 | D17: Overseas | E17: Unsold
A18: Cameron Green | B18: 20000000 | C18: 21300000 | D18: Overseas | E18: Sold | F18: Mumbai Indians (MI)
A19: Sanju Samson | B19: 15000000 | D19: Indian | E19: Unsold
A20: Shikhar Dhawan | B20: 15000000 | C20: 15300000 | D20: Indian | E20: Sold | F20: Delhi Capitals (DC)
A21: Rishabh Pant | B21: 20000000 | D21: Indian | E21: Unsold
A22: Kieron Pollard | B22: 15000000 | D22: Overseas | E22: Unsold
A23: Jofra Archer | B23: 15000000 | D23: Overseas | E23: Unsold
A24: Mohammed Shami | B24: 15000000 | D24: Indian | E24: Unsold
A25: Bhuvneshwar Kumar | B25: 15000000 | D25: Indian | E25: Unsold
A26: Sunil Narine | B26: 15000000 | D26: Overseas | E26: Unsold
A27: Nicholas Pooran | B27: 15000000 | D27: Overseas | E27: Unsold
A28: Kagiso Rabada | B28: 15000000 | D28: Overseas | E28: Unsold
A29: Yuzvendra Chahal | B29: 15000000 | D29: Indian | E29: Unsold
A30: Deepak Chahar | B30: 15000000 | D30: Indian | E30: Unsold
A31: R Ashwin | B31: 15000000 | D31: Indian | E31: Unsold
A32: Jason | B32: 15000000 | D32: Overseas | E32: Unsold
... A35: Moeen Ali | B35: 15000000 | D35: Overseas | E35: Unsold
A36: Josh Hazlewood | B36: 15000000 | C36: 15400000 | D36: Overseas | E36: Sold | F36: Delhi Capitals (DC)
A37: Shubman Gill | B37: 10000000 | D37: Indian | E37: Unsold
A38: Rahul Tewatia | B38: 10000000 | D38: Indian | E38: Unsold
A39: Manish Pandey | B39: 10000000 | C39: 11100000 | D39: Indian | E39: Sold | F39: Mumbai Indians (MI)
A40: Nitish Rana | B40: 10000000 | D40: Indian | E40: Unsold
A41: Mayank Agarwal | B41: 10000000 | D41: Indian | E41: Unsold
A42: T Natarajan | B42: 10000000 | D42: Indian | E42: Unsold
...

Sheet Sheet3
A1: Player Name | B1: Previous Contract/Retained Value (INR) | C1: Current Value (INR) | D1: Status | E1: Region | F1: Team
A2: MS Dhoni | B2: 12,00,00,000 | C2: 12,00,00,000 | D2: Sold | E2: India | F2: CSK
A3: Moeen Ali | B3: 8,00,00,000 | C3: 8,00,00,000 | D3: Sold | E3: England | F3: CSK
A4: Deepak Chahar | B4: 14,00,00,000 | C4: 14,00,00,000 | D4: Sold | E4: India | F4: CSK
A5: Devon Conway | B5: 1,00,00,000 | C5: 1,00,00,000 | D5: Sold | E5: New Zealand | F5: CSK
A6: Tushar Deshpande | B6: 20,00,000 | C6: 20,00,000 | D6: Sold | E6: India | F6: CSK
A7: Shivam Dube | B7: 4,00,00,000 | C7: 4,00,00,000 | D7: Sold | E7: India | F7: CSK
A8: Ruturaj Gaikwad | B8: 6,00,00,000 | C8: 6,00,00,000 | D8: Sold | E8: India | F8: CSK
A9: Rajvardhan Hangargekar | B9: 1,50,00,000 | C9: 1,50,00,000 | D9: Sold | E9: India | F9: CSK
A10: Ravindra Jadeja | B10: 16,00,00,000 | C10: 16,00,00,000 | D10: Sold | E10: India | F10: CSK
A11: Ajay Mandal | B11: 20,00,000 | C11: 20,00,00,000 | D11: Sold | E11: India | F11: CSK
A12: Mukesh Choudhary | B12: 20,00,000 | C12: 20,00,000 | D12: Sold | E12: India | F12: CSK
... A267: Prashant Chopra | B267: 20,00,000 | C267: N/A | D267: Unsold | E267: India | F267: N/A
